Workbook

Sheet Summary
A1: 132/33 kV substation: design summary
A2: Links to the calculation sheets. Change Inputs to resize.
A4: Item | B4: Result | C4: Unit
A5: Design load (N-1, with growth) | B5: =Transformer!$B$8 -> 48.96 | C5: MVA
A6: Transformers | B6: =Inputs!$B$20&" x "&Transformer!$B$9&" MVA, 132/33 kV, YNd11, Z "&Inputs!$B$21&"%" -> 2 x 50 MVA, 132/33 kV, YNd11, Z 12.5%
A7: Transformer loading, normal / N-1 now / N-1 design | B7: =TEXT(Transformer!$B$10,"0%")&" / "&TEXT(Transformer!$B$11,"0%")&" / "&TEXT(Transformer!$B$12,"0%") -> 41% / 82% / 98%
A8: Rated current 132 kV / 33 kV | B8: =TEXT(Transformer!$B$13,"0")&" A / "&TEXT(Transformer!$B$14,"0")&" A" -> 219 A / 875 A
A9: Fault level 132 kV bus | B9: =ShortCircuit!$B$10 -> 17.495463 | C9: kA
A10: Fault level 33 kV bus (coupler closed / open) | B10: =TEXT(ShortCircuit!$B$12,"0.0")&" / "&TEXT(ShortCircuit!$B$13,"0.0") -> 12.9 / 7.1 | C10: kA
A11: Breaker ratings 132 kV / 33 kV | B11: =ShortCircuit!$B$18&" / "&ShortCircuit!$B$19 -> 31.5 / 25 | C11: kA
A12: Busbars 132 kV / 33 kV | B12: =Equipment!$B$6&" / "&Equipment!$B$7 -> 1250 / 1250 | C12: A
A13: CT ratios: line / transformer HV / incomer / feeder | B13: =Equipment!$B$23&" / "&Equipment!$B$24&" / "&Equipment!$B$25&" / "&Equipment!$B$26 -> 600 / 300 / 1200 / 200 | C13: A / 1 A
A14: Arresters 132 kV / 33 kV | B14: =Equipment!$B$20&" / "&Equipment!$B$21 -> 120 / 36 | C14: kV
A15: NGR | B15: =TEXT(Transformer!$B$22,"0.0")&" ohm, "&Inputs!$B$25&" A" -> 63.5 ohm, 300 A
A16: Earth grid resistance | B16: =Earthing!$B$36 -> 0.72816129 | C16: ohm
A17: Ground potential rise | B17: =Earthing!$B$40 -> 9294.2097 | C17: V
A18: Touch voltage: Em vs tolerable | B18: =TEXT(Earthing!$B$53,"0")&" vs "&TEXT(Earthing!$B$43,"0") -> 621 vs 706 | C18: V
A20: Design checks
A21: Check | B21: Status
A22: Transformer N-1 loading at design load <= 100% | B22: =IF(Transformer!$B$12<=1,"OK","FAIL") -> OK
A23: Breaker rating >= 132 kV fault level | B23: =IF(ShortCircuit!$B$18>=ShortCircuit!$B$10,"OK","FAIL") -> OK
A24: Breaker rating >= 33 kV fault level | B24: =IF(ShortCircuit!$B$19>=ShortCircuit!$B$12,"OK","FAIL") -> OK
A25: Hand calculation within 5% of pandapower (33 kV) | B25: =IF(AND(ABS(ShortCircuit!$B$29)<0.05,ABS(ShortCircuit!$B$30)<0.05),"OK","CHECK") -> OK
A26: CT burden / VT burden | B26: =Equipment!$B$44 -> OK
A27: OC grading margins >= 0.3 s | B27: =Protection!$B$31 -> OK
A28: Transformer thermal withstand | B28: =Protection!$B$34 -> OK
A29: Earth-fault grading | B29: =Protection!$B$43 -> OK
A30: Earthing: touch voltage | B30: =Earthing!$B$58 -> OK
A31: Earthing: step voltage | B31: =Earthing!$B$59 -> OK
A32: Earthing: grid resistance <= 1 ohm | B32: =Earthing!$B$60 -> OK
A33: Overall | B33: =IF(COUNTIF(B22:B32,"OK")=11,"ALL CHECKS PASS","REVIEW") -> ALL CHECKS PASS
A35: Legend: blue on yellow = input; black = formula; green = link. Grid fault levels, soil resistivity and line data are assumptions.

Sheet Inputs
A1: Inputs and design basis: 132/33 kV substation
A2: Blue on yellow = editable input. Sheets recalculate from here.
A4: Parameter | B4: Value | C4: Unit | D4: Source / remark
A5: 1. System
A6: HV nominal voltage | B6: 132 | C6: kV | D6: Transmission-level supply
A7: HV highest system voltage Um | B7: 145 | C7: kV | D7: IEC 60038 / IEC 60071
A8: LV nominal voltage | B8: 33 | C8: kV
A9: LV highest system voltage Um | B9: 36 | C9: kV
A10: Frequency | B10: 50 | C10: Hz
A11: Grid short-circuit level at 132 kV, maximum (Sk'') | B11: 4000 | C11: MVA | D11: ASSUMPTION (17.5 kA). Obtain from the transmission utility
A12: Grid short-circuit level at 132 kV, minimum | B12: 2500 | C12: MVA | D12: ASSUMPTION (10.9 kA)
A13: IEC 60909 voltage factor c (max) | B13: 1.1 | C13: - | D13: HV system: 1.10
A14: 2. Load
A15: Number of 33 kV outgoing feeders | B15: 6 | C15: nos | D15: 3 on each bus section
A16: Design load per feeder | B16: 8 | C16: MVA | D16: Typical 33/11 kV substation feed
A17: Diversity factor | B17: 0.85 | C17: -
A18: Future growth margin | B18: 0.2 | C18: -
A19: 3. Transformer
A20: Number of transformers | B20: 2 | C20: nos | D20: N-1: either one must carry the full design load
A21: Transformer impedance | B21: 12.5 | C21: % | D21: IS 2026 typical for 50 MVA 132/33 kV
A22: OLTC range (HV side) | B22: 10 | C22: +/- % | D22: 16 steps of 1.25%
A23: Load loss at rated MVA | B23: 200 | C23: kW | D23: ASSUMPTION
A24: No-load loss | B24: 30 | C24: kW | D24: ASSUMPTION
A25: 33 kV neutral earthing: earth-fault current limit | B25: 300 | C25: A | D25: Resistance earthing through earthing transformer
A26: NGR / earthing transformer short-time rating | B26: 10 | C26: s
A27: 4. Equipment design
A28: Utility minimum standard breaking rating, 132 kV | B28: 31.5 | C28: kA | D28: Common utility practice
A29: Utility minimum standard breaking rating, 33 kV | B29: 25 | C29: kA | D29: Common utility practice
A30: Peak factor kappa (ip = kappa x sqrt2 x Ik'') | B30: 1.8 | C30: - | D30: Use 1.8 for HV (X/R high)
A31: Future transformer bays | B31: 1 | C31: nos | D31: 132 kV bus is sized for these
A32: Busbar design margin | B32: 1.25 | C32: -
A33: CT primary margin over rated current | B33: 1.2 | C33: -

Sheet Transformer
A1: Transformer sizing, ratings and earthing
A2: One 132/33 kV transformer. N-1 means one unit must carry the full 33 kV load.
A4: Parameter | B4: Value | C4: Unit | D4: Source / remark
A5: Load and rating
A6: Connected load | B6: =Inputs!$B$15*Inputs!$B$16 -> 48 | C6: MVA
A7: Peak demand = connected x diversity | B7: =Transformer!$B$6*Inputs!$B$17 -> 40.8 | C7: MVA
A8: Design load with growth | B8: =Transformer!$B$7*(1+Inputs!$B$18) -> 48.96 | C8: MVA | D8: Must be carried by one transformer (N-1)
A9: Selected transformer rating | B9: =IFERROR(INDEX(Std!$A$4:$A$10,COUNTIF(Std!$A$4:$A$10,"<"&(Transformer!$B$8))+1),"EXCEEDS LIST") -> 50 | C9: MVA | D9: Next standard size (ONAF rating)
A10: Loading, normal (both in service, load shared) | B10: =Transformer!$B$7/Inputs!$B$20/Transformer!$B$9 -> 0.408
A11: Loading, N-1 at present peak | B11: =Transformer!$B$7/Transformer!$B$9 -> 0.816
A12: Loading, N-1 at design load (with growth) | B12: =Transformer!$B$8/Transformer!$B$9 -> 0.9792 | D12: Should stay at or below 100%
A13: Rated current, 132 kV side | B13: =Transformer!$B$9*1000/(SQRT(3)*Inputs!$B$6) -> 218.69328 | C13: A
A14: Rated current, 33 kV side | B14: =Transformer!$B$9*1000/(SQRT(3)*Inputs!$B$8) -> 874.77314 | C14: A
A15: Feeder rated current | B15: =Inputs!$B$16*1000/(SQRT(3)*Inputs!$B$8) -> 139.9637 | C15: A
A16: Impedance and losses
A17: Transformer impedance, pu on own rating | B17: =Inputs!$B$21/100 -> 0.125 | C17: pu
A18: IEC 60909 correction factor KT = 0.95 c / (1 + 0.6 xT) | B18: =0.95*Inputs!$B$13/(1+0.6*Transformer!$B$17) -> 0.97209302
A19: Copper loss as % (for load flow models) | B19: =Inputs!$B$23/(Transformer!$B$9*1000)*100 -> 0.4 | C19: %
A20: Neutral earthing of the 33 kV system (earthing transformer + NGR)
A21: 33 kV phase voltage | B21: =Inputs!$B$8*1000/SQRT(3) -> 19052.559 | C21: V
A22: NGR resistance = Vph / IEF | B22: =Transformer!$B$21/Inputs!$B$25 -> 63.50853 | C22: ohm
A23: Earthing transformer short-time rating = Vph x IEF | B23: =Transformer!$B$21*Inputs!$B$25/1000 -> 5715.7677 | C23: kVA | D23: For the NGR time (10 s). Continuous rating much lower
A24: NGR power during fault | B24: =Transformer!$B$21*Inputs!$B$25/1000000 -> 5.7157677 | C24: MW
A25: Voltage regulation
A26: OLTC step | B26: =Inputs!$B$22/8 -> 1.25 | C26: % | D26: 16 steps total

Sheet ShortCircuit
A1: Short-circuit calculation (IEC 60909, per-unit on transformer MVA)
A2: Grid Sk'' already includes c. Z in pu. Cross-checked with pandapower below. Peak and breaker ratings follow.
A4: Parameter | B4: Value | C4: Unit | D4: Source / remark
A5: Per-unit impedances (base = transformer MVA)
A6: Grid impedance at max level = c x MVA_base / Sk'' | B6: =Inputs!$B$13*Transformer!$B$9/Inputs!$B$11 -> 0.01375 | C6: pu
A7: Grid impedance at min level = MVA_base / Sk'' | B7: =Transformer!$B$9/Inputs!$B$12 -> 0.02 | C7: pu
A8: Transformer impedance with KT | B8: =Transformer!$B$18*Transformer!$B$17 -> 0.12151163 | C8: pu
A9: Fault levels
A10: Ik'' at 132 kV bus (max) | B10: =Inputs!$B$11/(SQRT(3)*Inputs!$B$6) -> 17.495463 | C10: kA | D10: Sk'' / (sqrt3 x Un)
A11: Ik'' at 132 kV bus (min) | B11: =Inputs!$B$12/(SQRT(3)*Inputs!$B$6) -> 10.934664 | C11: kA
A12: Ik'' at 33 kV bus, coupler closed, both transformers (max) | B12: =Inputs!$B$13*Transformer!$B$14/(ShortCircuit!$B$6+ShortCircuit!$B$8/Inputs!$B$20)/1000 -> 12.915106 | C12: kA
A13: Ik'' at 33 kV bus, coupler open or one transformer (max) | B13: =Inputs!$B$13*Transformer!$B$14/(ShortCircuit!$B$6+ShortCircuit!$B$8)/1000 -> 7.1139943 | C13: kA
A14: Ik'' at 33 kV bus, coupler open (min) | B14: =1*Transformer!$B$14/(ShortCircuit!$B$7+Transformer!$B$17)/1000 -> 6.0329182 | C14: kA | D14: c = 1.0 for minimum case
A15: Peak current ip at 132 kV | B15: =Inputs!$B$30*SQRT(2)*ShortCircuit!$B$10 -> 44.536177 | C15: kA
A16: Peak current ip at 33 kV (coupler closed) | B16: =Inputs!$B$30*SQRT(2)*ShortCircuit!$B$12 -> 32.876491 | C16: kA
A17: Breaker and busbar rating (smallest standard value, not below utility minimum)
A18: 132 kV equipment short-circuit rating (3 s) | B18: =MAX(Inputs!$B$28,IFERROR(INDEX(Std!$B$4:$B$6,COUNTIF(Std!$B$4:$B$6,"<"&(ShortCircuit!$B$10))+1),"EXCEEDS LIST")) -> 31.5 | C18: kA
A19: 33 kV equipment short-circuit rating (3 s) | B19: =MAX(Inputs!$B$29,IFERROR(INDEX(Std!$C$4:$C$7,COUNTIF(Std!$C$4:$C$7,"<"&(ShortCircuit!$B$12))+1),"EXCEEDS LIST")) -> 25 | C19: kA
A20: Utilisation 132 kV (Ik'' / rating) | B20: =ShortCircuit!$B$10/ShortCircuit!$B$18 -> 0.55541151
A21: Utilisation 33 kV (Ik'' / rating) | B21: =ShortCircuit!$B$12/ShortCircuit!$B$19 -> 0.51660422
A22: Making capacity 132 kV (2.5 x rating) | B22: =2.5*ShortCircuit!$B$18 -> 78.75 | C22: kA peak
A23: Making capacity 33 kV (2.5 x rating) | B23: =2.5*ShortCircuit!$B$19 -> 62.5 | C23: kA peak
A24: Check with pandapower (IEC 60909 solver, see notebook)
A25: pandapower: 132 kV bus max | B25: =17.495 -> 17.495 | C25: kA | D25: Static value from the study run
A26: pandapower: 33 kV bus, coupler closed, max | B26: =12.919 -> 12.919 | C26: kA
A27: pandapower: 33 kV bus, coupler open, max | B27: =7.115 -> 7.115 | C27: kA
A28: pandapower: 33 kV bus, coupler open, min | B28: =6.035 -> 6.035 | C28: kA
A29: Difference hand vs pandapower, 33 kV closed | B29: =ShortCircuit!$B$12/ShortCircuit!$B$26-1 -> -0.0003014541
A30: Difference hand vs pandapower, 33 kV open | B30: =ShortCircuit!$B$13/ShortCircuit!$B$27-1 -> -0.0001413506
A31: Single-line-to-ground at 132 kV bus (pandapower, with transformer zero-sequence) | B31: =18.641 -> 18.641 | C31: kA | D31: Used for earthing design
A32: 33 kV earth-fault current (limited by NGR) | B32: =Inputs!$B$25/1000 -> 0.3 | C32: kA

Sheet Equipment
A1: Equipment ratings (per bay type)
A2: Current ratings from transformer and feeder data. Insulation levels per IEC 60071 (Um 145 kV: 650/275 kV; Um 36 kV: 170/70 kV).
A4: Parameter | B4: Value | C4: Unit | D4: Source / remark
A5: Busbars
A6: 132 kV busbar current rating = (transformers + future) x I_hv x margin | B6: =IFERROR(INDEX(Std!$D$4:$D$6,COUNTIF(Std!$D$4:$D$6,"<"&((Inputs!$B$20+Inputs!$B$31)*Transformer!$B$13*Inputs!$B$32))+1),"EXCEEDS LIST") -> 1250 | C6: A | D6: Tubular aluminium busbar
A7: 33 kV busbar current rating = I_lv x margin | B7: =IFERROR(INDEX(Std!$E$4:$E$8,COUNTIF(Std!$E$4:$E$8,"<"&(Transformer!$B$14*Inputs!$B$32))+1),"EXCEEDS LIST") -> 1250 | C7: A
A8: Circuit breakers
A9: 132 kV line / bus-section breaker current | B9: =IFERROR(INDEX(Std!$D$4:$D$6,COUNTIF(Std!$D$4:$D$6,"<"&(Inputs!$B$20*Transformer!$B$13*Inputs!$B$32))+1),"EXCEEDS LIST") -> 1250 | C9: A | D9: Line carries both transformers
A10: 132 kV transformer breaker current | B10: =IFERROR(INDEX(Std!$D$4:$D$6,COUNTIF(Std!$D$4:$D$6,"<"&(Transformer!$B$13*Inputs!$B$32))+1),"EXCEEDS LIST") -> 1250 | C10: A | D10: Smallest 132 kV standard is 1250 A
A11: 33 kV incomer / coupler breaker current | B11: =IFERROR(INDEX(Std!$E$4:$E$8,COUNTIF(Std!$E$4:$E$8,"<"&(Transformer!$B$14*1.1))+1),"EXCEEDS LIST") -> 1250 | C11: A
A12: 33 kV feeder breaker current | B12: =IFERROR(INDEX(Std!$E$4:$E$8,COUNTIF(Std!$E$4:$E$8,"<"&(Transformer!$B$15*Inputs!$B$32))+1),"EXCEEDS LIST") -> 630 | C12: A
A13: 132 kV breaker short-circuit rating | B13: =ShortCircuit!$B$18 -> 31.5 | C13: kA | D13: SF6, 3 s
A14: 33 kV breaker short-circuit rating | B14: =ShortCircuit!$B$19 -> 25 | C14: kA | D14: Vacuum, 3 s
A15: Insulation and arresters
A16: 132 kV lightning impulse withstand (LIWL) | B16: 650 | C16: kV | D16: IEC 60071-1 for Um 145 kV
A17: 132 kV power-frequency withstand (1 min) | B17: 275 | C17: kV
A18: 33 kV lightning impulse withstand (LIWL) | B18: 170 | C18: kV | D18: IEC 60071-1 for Um 36 kV
A19: 33 kV power-frequency withstand (1 min) | B19: 70 | C19: kV
A20: 132 kV arrester rated voltage = 0.8 x Um (effectively earthed) | B20: =ROUNDUP(0.8*Inputs!$B$7/6,0)*6 -> 120 | C20: kV | D20: Next multiple of 6: 120 kV
A21: 33 kV arrester rated voltage = Um (resistance earthed, not effectively earthed) | B21: =Inputs!$B$9 -> 36 | C21: kV | D21: 36 kV
A22: Current transformers (secondary 1 A at 132 kV and 33 kV)
A23: CT ratio, 132 kV line bay and bus section | B23: =IFERROR(INDEX(Std!$F$4:$F$15,COUNTIF(Std!$F$4:$F$15,"<"&(Inputs!$B$20*Transformer!$B$13*Inputs!$B$33))+1),"EXCEEDS LIST") -> 600 | C23: A / 1 A
A24: CT ratio, transformer HV bay | B24: =IFERROR(INDEX(Std!$F$4:$F$15,COUNTIF(Std!$F$4:$F$15,"<"&(Transformer!$B$13*Inputs!$B$33))+1),"EXCEEDS LIST") -> 300 | C24: A / 1 A
A25: CT ratio, 33 kV incomer and bus coupler | B25: =IFERROR(INDEX(Std!$F$4:$F$15,COUNTIF(Std!$F$4:$F$15,"<"&(Transformer!$B$14*Inputs!$B$33))+1),"EXCEEDS LIST") -> 1200 | C25: A / 1 A
A26: CT ratio, 33 kV feeder | B26: =IFERROR(INDEX(Std!$F$4:$F$15,COUNTIF(Std!$F$4:$F$15,"<"&(Transformer!$B$15*Inputs!$B$33))+1),"EXCEEDS LIST") -> 200 | C26: A / 1 A
A27: CT ratio, earthing transformer neutral | B27: =IFERROR(INDEX(Std!$F$4:$F$15,COUNTIF(Std!$F$4:$F$15,"<"&(Inputs!$B$25*1.2))+1),"EXCEEDS LIST") -> 400 | C27: A / 1 A
A28: CT short-time current (3 s) | B28: =ShortCircuit!$B$18 -> 31.5 | C28: kA | D28: same as breaker (132 kV); 33 kV CTs use the 33 kV rating
A29: CT knee-point voltage for the transformer differential (HV side)
A30: CT secondary resistance Rct | B30: 3 | C30: ohm | D30: Typical 1 A PS class
A31: Lead resistance (loop) | B31: 2.2 | C31: ohm | D31: About 150 m of 2.5 mm² each way
A32: Relay burden | B32: 0.05 | C32: ohm | D32: Numerical relay
A33: Through-fault current at HV side (33 kV fault, closed coupler) | B33: =ShortCircuit!$B$12*1000*Inputs!$B$8/Inputs!$B$6 -> 3228.7764 | C33: A | D33: Maximum external fault referred to HV
A34: Secondary current at that fault | B34: =Equipment!$B$33/Equipment!$B$24 -> 10.762588 | C34: A
A35: Required Vk = 2 x Is x (Rct + RL + Rr) | B35: =2*Equipment!$B$34*(Equipment!$B$30+Equipment!$B$31+Equipment!$B$32) -> 113.00717 | C35: V | D35: K = 2 stability factor
A36: Selected standard Vk | B36: =IFERROR(INDEX(Std!$G$4:$G$10,COUNTIF(Std!$G$4:$G$10,"<"&(Equipment!$B$35))+1),"EXCEEDS LIST") -> 200 | C36: V | D36: Specify class PS
A37: Voltage transformers
A38: CVT metering core (0.2) burden rating | B38: 50 | C38: VA | D38: 132 kV
A39: CVT protection core (3P) burden rating | B39: 100 | C39: VA
A40: Metering core connected burden (meters 8 VA + transducers 6 VA + cable 2 VA) | B40: 16 | C40: VA | D40: Should be 25-100% of rating
A41: Protection core connected burden (relays 10 VA + sync 5 VA + cable 15 VA) | B41: 30 | C41: VA | D41: Should be 25-100% of rating
...

Sheet Protection
A1: Protection settings and grading
A2: IEC Normal Inverse: t = TMS x 0.14 / ((I/Is)^0.02 - 1). Settings are proposed starting values for a relay-coordination study.
A4: Parameter | B4: Value | C4: Unit | D4: Source / remark
A5: 33 kV feeder (50/51, 50N/51N)
A6: Feeder CT primary | B6: 200 | C6: A | D6: From Equipment
A7: 51 pickup | B7: 175 | C7: A | D7: 1.25 x feeder current
A8: 51 TMS | B8: 0.1
A9: 50 instantaneous | B9: 1600 | C9: A | D9: 8 x CT
A10: 33 kV incomer (51)
A11: 51 pickup | B11: 1050 | C11: A | D11: 1.2 x rated
A12: 51 TMS | B12: 0.2
A13: 132 kV transformer backup (51)
A14: 51 pickup = 1.2 x rated, rounded up to 10 A | B14: =ROUNDUP(1.2*Transformer!$B$13/10,0)*10 -> 270 | C14: A
A15: 51 TMS | B15: 0.3
A16: 50 instantaneous = 1.3 x max 33 kV fault referred to HV | B16: =ROUNDUP(1.3*ShortCircuit!$B$12*1000*Inputs!$B$8/Inputs!$B$6/100,0)*100 -> 4200 | C16: A | D16: Must not operate for 33 kV faults
A17: Grading at 33 kV bus faults (feeder IDMT only; incomers carry half when coupler closed)
A18: Fault current: max, coupler closed | B18: =ShortCircuit!$B$12*1000 -> 12915.106 | C18: A
A19: Fault current: one transformer in service (N-1) | B19: =ShortCircuit!$B$13*1000 -> 7113.9943 | C19: A
A20: Fault current: min, coupler open | B20: =ShortCircuit!$B$14*1000 -> 6032.9182 | C20: A
A21: Feeder time, max | B21: =Protection!$B$8*0.14/((Protection!$B$18/Protection!$B$7)^0.02-1) -> 0.15583932 | C21: s
A22: Incomer time, max | B22: =Protection!$B$12*0.14/((Protection!$B$18/2/Protection!$B$11)^0.02-1) -> 0.75681454 | C22: s | D22: Half of the fault current
A23: HV 51 time, max | B23: =Protection!$B$15*0.14/((Protection!$B$18/2*Inputs!$B$8/Inputs!$B$6/Protection!$B$14)^0.02-1) -> 1.1534318 | C23: s
A24: Margin incomer over feeder, max | B24: =Protection!$B$22-Protection!$B$21 -> 0.60097522 | C24: s | D24: Need at least 0.3 s
A25: Margin HV over incomer, max | B25: =Protection!$B$23-Protection!$B$22 -> 0.39661723 | C25: s | D25: Need at least 0.3 s
A26: Feeder time, N-1 | B26: =Protection!$B$8*0.14/((Protection!$B$19/Protection!$B$7)^0.02-1) -> 0.18201862 | C26: s
A27: Incomer time, N-1 | B27: =Protection!$B$12*0.14/((Protection!$B$19/Protection!$B$11)^0.02-1) -> 0.7178194 | C27: s
A28: HV 51 time, N-1 | B28: =Protection!$B$15*0.14/((Protection!$B$19*Inputs!$B$8/Inputs!$B$6/Protection!$B$14)^0.02-1) -> 1.0931295 | C28: s
A29: Margin incomer over feeder, N-1 | B29: =Protection!$B$27-Protection!$B$26 -> 0.53580078 | C29: s
A30: Margin HV over incomer, N-1 | B30: =Protection!$B$28-Protection!$B$27 -> 0.37531013 | C30: s
A31: Grading check (all margins >= 0.3 s) | B31: =IF(MIN(Protection!$B$24,Protection!$B$25,Protection!$B$29,Protection!$B$30)>=0.3,"OK","INCREASE TMS") -> OK
A32: N-1 through-fault current in per unit of rated | B32: =Protection!$B$19/(Transformer!$B$14) -> 8.1323877 | C32: pu | D32: IEC 60076-5 allows 2 s at 1/Z
A33: Relay clearing time at that fault | B33: =Protection!$B$28 -> 1.0931295 | C33: s | D33: Must be below 2 s
A34: Thermal withstand check | B34: =IF(Protection!$B$28<2,"OK","FAIL") -> OK
A35: 33 kV earth fault (NGR-limited)
A36: Feeder 51N pickup | B36: 30 | C36: A | D36: 10% of NGR current
A37: Feeder 51N TMS | B37: 0.1
A38: Neutral (earthing transformer) 51N pickup | B38: 60 | C38: A | D38: 20% of NGR current
A39: Neutral 51N TMS | B39: 0.2
A40: Feeder 51N time at NGR current | B40: =Protection!$B$37*0.14/((Inputs!$B$25/Protection!$B$36)^0.02-1) -> 0.29705986 | C40: s
A41: Neutral 51N time at NGR current | B41: =Protection!$B$39*0.14/((Inputs!$B$25/Protection!$B$38)^0.02-1) -> 0.85594401 | C41: s
...

Sheet Earthing
A1: Earthing grid design (IEEE Std 80 method)
A2: Soil resistivity is an ASSUMPTION: a Wenner survey of the site is mandatory before construction.
A4: Parameter | B4: Value | C4: Unit | D4: Source / remark
A5: Inputs
A6: Grid length | B6: 70 | C6: m | D6: Switchyard + control building area
A7: Grid width | B7: 60 | C7: m
A8: Soil resistivity | B8: 100 | C8: ohm.m | D8: ASSUMPTION (survey needed)
A9: Surface layer resistivity (crushed rock) | B9: 3000 | C9: ohm.m
A10: Surface layer thickness | B10: 0.15 | C10: m
A11: Burial depth of grid | B11: 0.6 | C11: m
A12: Maximum earth-fault current 3I0 (design value) | B12: 20 | C12: kA | D12: Study value 18.6 kA at 132 kV bus, rounded up
A13: Current division factor Sf | B13: 0.6 | C13: - | D13: Share flowing into the grid; rest returns via earth wires and neutrals
A14: Fault clearing time | B14: 1 | C14: s | D14: Backup clearing time, conservative
A15: System X/R at fault | B15: 20 | C15: -
A16: Material constant Kf (steel 1020) | B16: 15.95 | C16: - | D16: IEEE 80 Table 2
A17: Conductor spacing | B17: 5 | C17: m | D17: Chosen to pass the touch-voltage check
A18: Number of earth rods | B18: 40 | C18: nos | D18: On the perimeter and at corners
A19: Rod length | B19: 3 | C19: m
A20: Flat conductor width | B20: 75 | C20: mm
A21: Flat conductor thickness | B21: 12 | C21: mm | D21: Mild steel flat, galvanised
A22: Conductor
A23: Minimum conductor area = If x Kf x sqrt(tf) x 0.5067 | B23: =Earthing!$B$12*Earthing!$B$16*SQRT(Earthing!$B$14)*0.5067 -> 161.6373 | C23: mm²
A24: Selected flat area | B24: =Earthing!$B$20*Earthing!$B$21 -> 900 | C24: mm²
A25: Conductor check | B25: =IF(Earthing!$B$24>=Earthing!$B$23*2,"OK (with 2x margin for corrosion)","CHECK") -> OK (with 2x margin for corrosion)
A26: Geometry
A27: Area | B27: =Earthing!$B$6*Earthing!$B$7 -> 4200 | C27: m²
A28: Conductors along width direction | B28: =ROUND(Earthing!$B$6/Earthing!$B$17,0)+1 -> 15 | C28: nos
A29: Conductors along length direction | B29: =ROUND(Earthing!$B$7/Earthing!$B$17,0)+1 -> 13 | C29: nos
A30: Total horizontal conductor length | B30: =Earthing!$B$6*Earthing!$B$29+Earthing!$B$7*Earthing!$B$28 -> 1810 | C30: m
A31: Perimeter | B31: =2*(Earthing!$B$6+Earthing!$B$7) -> 260 | C31: m
A32: Total rod length | B32: =Earthing!$B$18*Earthing!$B$19 -> 120 | C32: m
A33: Total buried conductor length | B33: =Earthing!$B$30+Earthing!$B$32 -> 1930 | C33: m
A34: Equivalent conductor diameter = 2(w+t)/pi | B34: =2*(Earthing!$B$20+Earthing!$B$21)/PI()/1000 -> 0.05538592 | C34: m
A35: Resistance and potential rise
A36: Grid resistance Rg (Sverak) | B36: =Earthing!$B$8*(1/Earthing!$B$33+1/SQRT(20*Earthing!$B$27)*(1+1/(1+Earthing!$B$11*SQRT(20/Earthing!$B$27)))) -> 0.72816129 | C36: ohm | D36: Target at or below 1 ohm
A37: DC offset time constant Ta = X/R / (2 pi f) | B37: =Earthing!$B$15/(2*PI()*Inputs!$B$10) -> 0.063661977 | C37: s
A38: Decrement factor Df | B38: =1+Earthing!$B$37/Earthing!$B$14*(1-EXP(-2*Earthing!$B$14/Earthing!$B$37)) -> 1.063662
A39: Grid current Ig = Sf x If x Df | B39: =Earthing!$B$13*Earthing!$B$12*1000*Earthing!$B$38 -> 12763.944 | C39: A
A40: Ground potential rise GPR = Ig x Rg | B40: =Earthing!$B$39*Earthing!$B$36 -> 9294.2097 | C40: V
A41: Tolerable voltages (70 kg body)
...

Sheet BOM
A1: Major equipment list (no prices)
A2: Quantities from the single line diagram. Edit counts if you change the layout.
A4: Item | B4: Description | C4: Qty
A5: Power transformer | B5: ="132/33 kV, "&TEXT(Transformer!$B$9,"0")&" MVA ONAN/ONAF, YNd11, Z = "&TEXT(Inputs!$B$21,"0.0")&"%, OLTC +/-"&TEXT(Inputs!$B$22,"0")&"%" -> 132/33 kV, 50 MVA ONAN/ONAF, YNd11, Z = 12.5%, OLTC +/-10% | C5: =Inputs!$B$20 -> 2
A6: 132 kV SF6 circuit breaker | B6: ="145 kV, "&Equipment!$B$9&" A, "&Equipment!$B$13&" kA / 3 s (line, bus section), "&Equipment!$B$10&" A (transformer)" -> 145 kV, 1250 A, 31.5 kA / 3 s (line, bus section), 1250 A (transformer) | C6: =2+1+Inputs!$B$20 -> 5
A7: 132 kV isolator (double break), line isolators with earth switch | B7: ="145 kV, "&Equipment!$B$10&" A, "&Equipment!$B$13&" kA" -> 145 kV, 1250 A, 31.5 kA | C7: =2*2+Inputs!$B$20+2 -> 8
A8: 132 kV CT (3 phase sets) | B8: =TEXT(Equipment!$B$23,"0")&"/1 (line, bus section), "&TEXT(Equipment!$B$24,"0")&"/1 (transformer), 4-5 cores" -> 600/1 (line, bus section), 300/1 (transformer), 4-5 cores | C8: =2+1+Inputs!$B$20 -> 5
A9: 132 kV capacitor voltage transformer (3 phase sets) | B9: ="132/V3 kV : 110/V3 V, 0.2 / 3P / 3P" -> 132/V3 kV : 110/V3 V, 0.2 / 3P / 3P | C9: =2+2 -> 4
A10: 132 kV surge arrester (3 phase sets) | B10: =Equipment!$B$20&" kV, 10 kA, station class" -> 120 kV, 10 kA, station class | C10: =2+Inputs!$B$20 -> 4
A11: 132 kV busbar | B11: ="Tubular, "&Equipment!$B$6&" A, 2 sections" -> Tubular, 1250 A, 2 sections | C11: =2 -> 2
A12: 33 kV vacuum circuit breaker (incomer and coupler) | B12: ="36 kV, "&Equipment!$B$11&" A, "&Equipment!$B$14&" kA / 3 s" -> 36 kV, 1250 A, 25 kA / 3 s | C12: =Inputs!$B$20+1 -> 3
A13: 33 kV vacuum circuit breaker (feeder) | B13: ="36 kV, "&Equipment!$B$12&" A, "&Equipment!$B$14&" kA / 3 s" -> 36 kV, 630 A, 25 kA / 3 s | C13: =Inputs!$B$15 -> 6
A14: 33 kV vacuum circuit breaker (earthing transformer) | B14: ="36 kV, "&Equipment!$B$12&" A, "&Equipment!$B$14&" kA / 3 s" -> 36 kV, 630 A, 25 kA / 3 s | C14: =2 -> 2
A15: 33 kV isolator (incomers, coupler, feeders, earthing transformers, PT) | B15: ="36 kV, "&Equipment!$B$11&" A" -> 36 kV, 1250 A | C15: =Inputs!$B$20+2+Inputs!$B$15+2+2 -> 14
A16: 33 kV CT sets | B16: =TEXT(Equipment!$B$25,"0")&"/1 (incomer, coupler), "&TEXT(Equipment!$B$26,"0")&"/1 (feeder), "&TEXT(Equipment!$B$27,"0")&"/1 (neutral)" -> 1200/1 (incomer, coupler), 200/1 (feeder), 400/1 (neutral) | C16: =Inputs!$B$20+1+Inputs!$B$15+2 -> 11
A17: 33 kV voltage transformer (3 phase sets) | B17: ="33/V3 kV : 110/V3 V, 0.5 / 3P" -> 33/V3 kV : 110/V3 V, 0.5 / 3P | C17: =2 -> 2
A18: 33 kV surge arrester | B18: =Equipment!$B$21&" kV, 10 kA" -> 36 kV, 10 kA | C18: =Inputs!$B$15+Inputs!$B$20 -> 8
A19: Earthing transformer (zig-zag) with 415 V aux winding | B19: =TEXT(Transformer!$B$23,"#,##0")&" kVA for "&Inputs!$B$26&" s, "&Inputs!$B$25&" A" -> 5,716 kVA for 10 s, 300 A | C19: =2 -> 2
A20: Neutral earthing resistor | B20: =TEXT(Transformer!$B$22,"0.0")&" ohm, "&Inputs!$B$25&" A, "&Inputs!$B$26&" s" -> 63.5 ohm, 300 A, 10 s | C20: =2 -> 2
A21: Numerical protection relays (approximate count) | B21: ="Line (21), transformer (87T, 51), feeder (50/51), bus (87B), 25, 50BF" -> Line (21), transformer (87T, 51), feeder (50/51), bus (87B), 25, 50BF | C21: =2+2*2+Inputs!$B$15+3+2+2 -> 19
A22: Earthing grid | B22: =TEXT(Earthing!$B$6,"0")&" x "&TEXT(Earthing!$B$7,"0")&" m, "&TEXT(Earthing!$B$20,"0")&"x"&TEXT(Earthing!$B$21,"0")&" mm MS flat at "&TEXT(Earthing!$B$17,"0")&" m spacing, "&Earthing!$B$18&" rods x "&Earthing!$B$19&" m" -> 70 x 60 m, 75x12 mm MS flat at 5 m spacing, 40 rods x 3 m | C22: =1 -> 1
A23: DC system | B23: ="110 V, 2 x 100% battery banks and chargers" -> 110 V, 2 x 100% battery banks and chargers | C23: =2 -> 2

Sheet Std
A1: Standard ratings (edit if your vendor differs)
A3: Transformer (MVA) | B3: 132 kV breaking (kA) | C3: 33 kV breaking (kA) | D3: 132 kV equipment current (A) | E3: 33 kV equipment current (A) | F3: CT primary (A) | G3: CT knee-point Vk (V)
A4: 20 | B4: 25 | C4: 16 | D4: 1250 | E4: 630 | F4: 50 | G4: 100
A5: 31.5 | B5: 31.5 | C5: 25 | D5: 2000 | E5: 1250 | F5: 100 | G5: 200
A6: 40 | B6: 40 | C6: 31.5 | D6: 3150 | E6: 2000 | F6: 150 | G6: 300
A7: 50 | C7: 40 | E7: 2500 | F7: 200 | G7: 400
A8: 63 | E8: 3150 | F8: 300 | G8: 600
A9: 80 | F9: 400 | G9: 800
A10: 100 | F10: 600 | G10: 1000
F11: 800
F12: 1000
F13: 1200
F14: 1600
F15: 2000
